Workbook

Sheet 표1_논문데이터
A1: 표 1. 박상혁 등(2022) 포항시 음식물류폐기물 월별 성상 (원물, 2020.11~2021.10)
A2: 파란 글씨=입력값. TS·VS·TVFAs·TAN·pH·탄수화물·단백질·지방·COD·SCOD는 Fig.1을 픽셀 단위로 디지타이징한 값(축 눈금 보정, 본문 명시값 대조 완료, 오차 약 ±1~3%), BMP·Rm은 Table 2 원문값(modified Gompertz).
A3: 월 | B3: TS | C3: VS | D3: TVFAs | E3: TAN | F3: pH | G3: 탄수화물 | H3: 단백질 | I3: 지방 | J3: COD | K3: SCOD | L3: BMP (COD 기준) | M3: BMP (VS 기준) | N3: Rm (최대 메탄생성율) | O3: 본문·표 대조
B4: g/L | C4: g/L | D4: g/L | E4: g/L | F4: - | G4: % VS | H4: % VS | I4: % VS | J4: g/L | K4: g/L | L4: mL CH₄/g COD | M4: mL CH₄/g VS | N4: mL CH₄/g COD/d
A5: 1월 | B5: 204.2 | C5: 184 | D5: 6.11 | E5: 0.464 | F5: 5.28 | G5: 26.89 | H5: 35.23 | I5: 10.84 | J5: 314.5 | K5: 89.3 | L5: 266.43 | M5: 475.77 | N5: 58.27 | O5: 탄수화물 본문 26.82 ✓
A6: 2월 | B6: 213.6 | C6: 190.7 | D6: 3.38 | E6: 0.668 | F6: 5.46 | G6: 15.51 | H6: 40.92 | I6: 19.17 | J6: 380.4 | K6: 94.8 | L6: 277.59 | M6: 550.02 | N6: 93.52 | O6: 탄수화물 15.57, 지방 19.28 ✓
A7: 3월 | B7: 220.7 | C7: 203 | D7: 3.38 | E7: 0.473 | F7: 5 | G7: 40.51 | H7: 27.91 | I7: 14.5 | J7: 265.1 | K7: 94.8 | L7: 263.59 | M7: 504.48 | N7: 94.28
A8: 4월 | B8: 181.3 | C8: 152.3 | D8: 1.86 | E8: 0.8 | F8: 4.94 | G8: 22.02 | H8: 61.04 | I8: 13.28 | J8: 318.2 | K8: 101.2 | L8: 273.99 | M8: 570.54 | N8: 90.12 | O8: 단백질 61.12 ✓
A9: 5월 | B9: 176.7 | C9: 152.9 | D9: 2.29 | E9: 0.658 | F9: 4.67 | G9: 30.15 | H9: 51.49 | I9: 18.97 | J9: 315.4 | K9: 95.7 | L9: 254.47 | M9: 526.62 | N9: 99.35 | O9: 단백질 51.49, 지방 18.96 ✓
A10: 6월 | B10: 182.2 | C10: 156.6 | D10: 3.3 | E10: 0.692 | F10: 4.45 | G10: 57.59 | H10: 22.02 | I10: 12.67 | J10: 242.2 | K10: 191.8 | L10: 229.86 | M10: 351.34 | N10: 70.6 | O10: 탄수화물 57.54~57.67(6~7월) ✓
A11: 7월 | B11: 264 | C11: 250.6 | D11: 2.33 | E11: 0.46 | F11: 4.25 | G11: 57.59 | H11: 19.17 | I11: 21.61 | J11: 317.2 | K11: 197.3 | L11: 259.89 | M11: 328.25 | N11: 73.85 | O11: 지방 21.87, pH 4.25 ✓
A12: 8월 | B12: 190.7 | C12: 162.7 | D12: 4.91 | E12: 0.682 | F12: 4.2 | G12: 28.11 | H12: 36 | I12: 12.06 | J12: 218.4 | K12: 179.9 | L12: 262.16 | M12: 349.74 | N12: 62.58 | O12: pH 4.20 ✓
A13: 9월 | B13: 125.4 | C13: 118.1 | D13: 1.88 | E13: 0.332 | F13: 4.65 | G13: 51.89 | H13: 33.4 | I13: 14.7 | J13: 146 | K13: 109.4 | L13: 258.06 | M13: 313.88 | N13: 64.94
A14: 10월 | B14: 166.3 | C14: 151.4 | D14: 3.3 | E14: 0.534 | F14: 4.94 | G14: 55.35 | H14: 23.03 | I14: 13.28 | J14: 216.5 | K14: 168 | L14: =AVERAGE(L13,L15) -> 261.815 | M14: =AVERAGE(M13,M15) -> 364.36 | N14: =AVERAGE(N13,N15) -> 91.48 | O14: BMP·Rm 미시험 → 9·11월 평균으로 보간(검정 수식)
A15: 11월 | B15: 208.4 | C15: 185.2 | D15: 3.87 | E15: 0.499 | F15: 4.64 | G15: 47.63 | H15: 25.47 | I15: 10.23 | J15: 311.8 | K15: 92 | L15: 265.57 | M15: 414.84 | N15: 118.02 | O15: 지방 10.10 ✓
A16: 12월 | B16: 213.3 | C16: 196.2 | D16: 5.9 | E16: 0.324 | F16: 5.09 | G16: 35.63 | H16: 36.45 | I16: 14.5 | J16: 307.2 | K16: 127.7 | L16: 248.04 | M16: 379.8 | N16: 50.54
A18: 주: TS≥200 g/L인 월은 PyADM1ODE가 고형물 밀도식으로 분기합니다. 전처리 전 원물 값이며 중간저장조 값이 아닙니다.
A19: 주: 월 값은 월 1~2회 시료의 평균(막대)이며 오차막대는 논문 Fig.1 참조. 본문 평균과의 대조: SCOD 9~5월 평균 108.1(본문 108.31), 6~8월 189.7(본문 189.43), 겨울 TS 209.9(본문 211.68).

Sheet 표2_YAML변수
A1: 표 2. PyADM1ODE 기질 YAML 17개 변수 — 월별 추정 (원물 기준)
A2: 검정=수식, 초록=표1 직접 인용, 파란=입력. 계산은 표1과 [가정] 시트의 상수를 참조하므로 가정을 바꾸면 자동 갱신됩니다. 아래 보조 계산 행을 함께 보세요.
A4: 변수 | B4: 단위 | C4: 1월 | D4: 2월 | E4: 3월 | F4: 4월 | G4: 5월 | H4: 6월 | I4: 7월 | J4: 8월 | K4: 9월 | L4: 10월 | M4: 11월 | N4: 12월 | O4: 산정 방법 / 계산식
A5: TS | B5: kg/t FM | C5: =IF(C38<200,C38,IF(C39>=200,C39,IF(ABS((0.2/((C28)*0.2+C29)*C26)-C37)<=ABS((0.19999*1000*C26)-C37),200,199.99))) -> 25.636977 | D5: =IF(D38<200,D38,IF(D39>=200,D39,IF(ABS((0.2/((D28)*0.2+D29)*D26)-D37)<=ABS((0.19999*1000*D26)-D37),200,199.99))) -> 28.194458 | E5: =IF(E38<200,E38,IF(E39>=200,E39,IF(ABS((0.2/((E28)*0.2+E29)*E26)-E37)<=ABS((0.19999*1000*E26)-E37),200,199.99))) -> 20.553921 | F5: =IF(F38<200,F38,IF(F39>=200,F39,IF(ABS((0.2/((F28)*0.2+F29)*F26)-F37)<=ABS((0.19999*1000*F26)-F37),200,199.99))) -> 26.230934 | G5: =IF(G38<200,G38,IF(G39>=200,G39,IF(ABS((0.2/((G28)*0.2+G29)*G26)-G37)<=ABS((0.19999*1000*G26)-G37),200,199.99))) -> 23.843492 | H5: =IF(H38<200,H38,IF(H39>=200,H39,IF(ABS((0.2/((H28)*0.2+H29)*H26)-H37)<=ABS((0.19999*1000*H26)-H37),200,199.99))) -> 20.785 | I5: =IF(I38<200,I38,IF(I39>=200,I39,IF(ABS((0.2/((I28)*0.2+I29)*I26)-I37)<=ABS((0.19999*1000*I26)-I37),200,199.99))) -> 22.213672 | J5: =IF(J38<200,J38,IF(J39>=200,J39,IF(ABS((0.2/((J28)*0.2+J29)*J26)-J37)<=ABS((0.19999*1000*J26)-J37),200,199.99))) -> 18.418265 | ... N5: =IF(N38<200,N38,IF(N39>=200,N39,IF(ABS((0.2/((N28)*0.2+N29)*N26)-N37)<=ABS((0.19999*1000*N26)-N37),200,199.99))) -> 23.325513 | O5: 희석 후 모델 총 COD = R·실측 COD 가 되도록 산정. R=1/(1+w_water). TS<200이면 X/q, 아니면 밀도식 폐형해 X·B/(q−X·A)×1000
A6: NH4 | B6: kg N/m³ | C6: =표1_논문데이터!$E$5*C31 -> 0.0464 | D6: =표1_논문데이터!$E$6*D31 -> 0.0668 | E6: =표1_논문데이터!$E$7*E31 -> 0.0473 | F6: =표1_논문데이터!$E$8*F31 -> 0.08 | G6: =표1_논문데이터!$E$9*G31 -> 0.0658 | H6: =표1_논문데이터!$E$10*H31 -> 0.0692 | I6: =표1_논문데이터!$E$11*I31 -> 0.046 | J6: =표1_논문데이터!$E$12*J31 -> 0.0682 | K6: =표1_논문데이터!$E$13*K31 -> 0.0332 | L6: =표1_논문데이터!$E$14*L31 -> 0.0534 | M6: =표1_논문데이터!$E$15*M31 -> 0.0499 | N6: =표1_논문데이터!$E$16*N31 -> 0.0324 | O6: TAN_m × R (물로 희석)
A7: BGP | B7: Nm³/t VS | C7: =C8/C50 -> 796.45496 | D7: =D8/D50 -> 877.72817 | E7: =E8/E50 -> 850.52929 | F7: =F8/F50 -> 875.05349 | G7: =G8/G50 -> 816.18427 | H7: =H8/H50 -> 607.62865 | I7: =I8/I50 -> 551.8363 | J7: =J8/J50 -> 581.1244 | ... N7: =N8/N50 -> 624.28155 | O7: BMP_VS,m / f_CH4,m , f_CH4=ΣX_i / Σ(X_i/MP_i) (참고용, 모델 계산에 미사용)
A8: BMP | B8: Nm³ CH₄/t VS | C8: =표1_논문데이터!$M$5 -> 475.77 | D8: =표1_논문데이터!$M$6 -> 550.02 | E8: =표1_논문데이터!$M$7 -> 504.48 | F8: =표1_논문데이터!$M$8 -> 570.54 | G8: =표1_논문데이터!$M$9 -> 526.62 | H8: =표1_논문데이터!$M$10 -> 351.34 | I8: =표1_논문데이터!$M$11 -> 328.25 | J8: =표1_논문데이터!$M$12 -> 349.74 | K8: =표1_논문데이터!$M$13 -> 313.88 | L8: =표1_논문데이터!$M$14 -> 364.36 | M8: =표1_논문데이터!$M$15 -> 414.84 | N8: =표1_논문데이터!$M$16 -> 379.8 | O8: 논문 Table 2 VS 기준 BMP (10월은 9·11월 평균 보간) (참고용)
A9: aXI | B9: - | C9: =C44*가정!$C$25 -> 0.12978611 | D9: =D44*가정!$C$25 -> 0.10549536 | E9: =E44*가정!$C$25 -> 0.13467973 | F9: =F44*가정!$C$25 -> 0.11248754 | G9: =G44*가정!$C$25 -> 0.15249884 | H9: =H44*가정!$C$25 -> 0.20412422 | I9: =I44*가정!$C$25 -> 0.14144957 | J9: =J44*가정!$C$25 -> 0.1390793 | ... N9: =N44*가정!$C$25 -> 0.16777682 | O9: a_total,m × share_XI(2/3)
A10: fOTSrf | B10: - | C10: =가정!$C$6 -> 0.8 | D10: =가정!$C$6 -> 0.8 | E10: =가정!$C$6 -> 0.8 | F10: =가정!$C$6 -> 0.8 | G10: =가정!$C$6 -> 0.8 | H10: =가정!$C$6 -> 0.8 | I10: =가정!$C$6 -> 0.8 | J10: =가정!$C$6 -> 0.8 | ... N10: =가정!$C$6 -> 0.8 | O10: 가정 상수 0.80 (논문에 없음)
A11: fsOTS | B11: - | C11: =1-C12 -> 0 | D11: =1-D12 -> 0 | E11: =1-E12 -> 0 | F11: =1-F12 -> 0 | G11: =1-G12 -> 0 | H11: =1-H12 -> 0 | I11: =1-I12 -> 0 | J11: =1-J12 -> 0 | ... N11: =1-N12 -> 0 | O11: 1 − ffOTS,m (= 0)
A12: ffOTS | B12: - | C12: =가정!$C$27 -> 1 | D12: =가정!$C$27 -> 1 | E12: =가정!$C$27 -> 1 | F12: =가정!$C$27 -> 1 | G12: =가정!$C$27 -> 1 | H12: =가정!$C$27 -> 1 | I12: =가정!$C$27 -> 1 | J12: =가정!$C$27 -> 1 | ... N12: =가정!$C$27 -> 1 | O12: 1.0 (가정 시트 ffOTS_FW). 근거: 논문 Rm/BMP_COD = 0.20~0.44 d⁻¹ (k_1st 행) ≈ ADM1da 빠른 풀 0.4 d⁻¹ ≫ 느린 풀 0.04. SCOD 기반 분할값은 참고 행에 유지
A13: aSi | B13: - | C13: =C44*(1-가정!$C$25) -> 0.064893055 | D13: =D44*(1-가정!$C$25) -> 0.052747682 | E13: =E44*(1-가정!$C$25) -> 0.067339865 | F13: =F44*(1-가정!$C$25) -> 0.05624377 | G13: =G44*(1-가정!$C$25) -> 0.07624942 | H13: =H44*(1-가정!$C$25) -> 0.10206211 | I13: =I44*(1-가정!$C$25) -> 0.070724787 | J13: =J44*(1-가정!$C$25) -> 0.06953965 | ... N13: =N44*(1-가정!$C$25) -> 0.083888412 | O13: a_total,m × (1 − share_XI)
A14: fRF | B14: -TS | C14: =가정!$C$5 -> 0.04 | D14: =가정!$C$5 -> 0.04 | E14: =가정!$C$5 -> 0.04 | F14: =가정!$C$5 -> 0.04 | G14: =가정!$C$5 -> 0.04 | H14: =가정!$C$5 -> 0.04 | I14: =가정!$C$5 -> 0.04 | J14: =가정!$C$5 -> 0.04 | ... N14: =가정!$C$5 -> 0.04 | O14: 가정 상수 0.04 (논문에 없음)
A15: fRP | B15: -TS | C15: =표1_논문데이터!$H$5/100*C24 -> 0.31744956 | D15: =표1_논문데이터!$H$6/100*D24 -> 0.36532978 | E15: =표1_논문데이터!$H$7/100*E24 -> 0.25671636 | F15: =표1_논문데이터!$H$8/100*F24 -> 0.51276293 | G15: =표1_논문데이터!$H$9/100*G24 -> 0.44554731 | H15: =표1_논문데이터!$H$10/100*H24 -> 0.18926081 | I15: =표1_논문데이터!$H$11/100*I24 -> 0.18196977 | J15: =표1_논문데이터!$H$12/100*J24 -> 0.30714211 | K15: =표1_논문데이터!$H$13/100*K24 -> 0.31455662 | L15: =표1_논문데이터!$H$14/100*L24 -> 0.20966578 | M15: =표1_논문데이터!$H$15/100*M24 -> 0.22634568 | N15: =표1_논문데이터!$H$16/100*N24 -> 0.33527848 | O15: 단백질(%VS)/100 × VS/TS
A16: fRFe | B16: -TS | C16: =표1_논문데이터!$I$5/100*C24 -> 0.097676787 | D16: =표1_논문데이터!$I$6/100*D24 -> 0.17114789 | E16: =표1_논문데이터!$I$7/100*E24 -> 0.13337109 | F16: =표1_논문데이터!$I$8/100*F24 -> 0.11155786 | G16: =표1_논문데이터!$I$9/100*G24 -> 0.16414901 | H16: =표1_논문데이터!$I$10/100*H24 -> 0.10889802 | I16: =표1_논문데이터!$I$11/100*I24 -> 0.20513129 | J16: =표1_논문데이터!$I$12/100*J24 -> 0.10289261 | K16: =표1_논문데이터!$I$13/100*K24 -> 0.13844258 | L16: =표1_논문데이터!$I$14/100*L24 -> 0.1209015 | M16: =표1_논문데이터!$I$15/100*M24 -> 0.090911516 | N16: =표1_논문데이터!$I$16/100*N24 -> 0.13337553 | O16: 지방(%VS)/100 × VS/TS
A17: fRA | B17: -TS | C17: =1-C24 -> 0.098922625 | D17: =1-D24 -> 0.10720974 | E17: =1-E24 -> 0.080199366 | F17: =1-F24 -> 0.15995587 | G17: =1-G24 -> 0.13469157 | H17: =1-H24 -> 0.14050494 | I17: =1-I24 -> 0.050757576 | J17: =1-J24 -> 0.14682748 | ... N17: =1-N24 -> 0.080168776 | O17: 1 − VS/TS
A18: Temp | B18: °C | C18: 35 | D18: 35 | E18: 35 | F18: 35 | G18: 35 | H18: 35 | I18: 35 | J18: 35 | K18: 35 | L18: 35 | M18: 35 | N18: 35 | O18: 실측 입력값 35 (사용자 제공). 모델 계산식에는 쓰이지 않고 Kw·Ka 등 35℃ 상수와 일치
A19: pH | B19: - | C19: 7 | D19: 7 | E19: 7 | F19: 7 | G19: 7 | H19: 7 | I19: 7 | J19: 7 | K19: 7 | L19: 7 | M19: 7 | N19: 7 | O19: 실측 입력값 7 (사용자 제공, 중간저장조). 표1의 원물 pH와 다름
A20: KS43 | B20: mol/m³ | C20: =C53+C54 -> 7.4969759 | D20: =D53+D54 -> 4.1472633 | E20: =E53+E54 -> 4.1472633 | F20: =F53+F54 -> 2.2822218 | G20: =G53+G54 -> 2.8098322 | H20: =H53+H54 -> 4.0491032 | I20: =I53+I54 -> 2.8589123 | J20: =J53+J54 -> 6.0245748 | ... N20: =N53+N54 -> 7.2393057 | O20: KS43_vfa + ΔKS43(약품). KS43_vfa = max(0, FFS/60.05×1000×[α(pH)−α(4.3)]), ΔKS43 = dose_on·max(0, KS43_tgt − KS43_vfa)
A21: FFS | B21: kg HAc/m³ | C21: =표1_논문데이터!$D$5*C31 -> 0.611 | D21: =표1_논문데이터!$D$6*D31 -> 0.338 | E21: =표1_논문데이터!$D$7*E31 -> 0.338 | F21: =표1_논문데이터!$D$8*F31 -> 0.186 | G21: =표1_논문데이터!$D$9*G31 -> 0.229 | H21: =표1_논문데이터!$D$10*H31 -> 0.33 | I21: =표1_논문데이터!$D$11*I31 -> 0.233 | J21: =표1_논문데이터!$D$12*J31 -> 0.491 | K21: =표1_논문데이터!$D$13*K31 -> 0.188 | L21: =표1_논문데이터!$D$14*L31 -> 0.33 | M21: =표1_논문데이터!$D$15*M31 -> 0.387 | N21: =표1_논문데이터!$D$16*N31 -> 0.59 | O21: TVFAs_m × R (물로 희석, 아세트산 환산 근사)
A23: 보조 계산 (표2 산정용)
A24: VS/TS | B24: - | C24: =표1_논문데이터!$C$5/표1_논문데이터!$B$5 -> 0.90107738 | D24: =표1_논문데이터!$C$6/표1_논문데이터!$B$6 -> 0.89279026 | E24: =표1_논문데이터!$C$7/표1_논문데이터!$B$7 -> 0.91980063 | F24: =표1_논문데이터!$C$8/표1_논문데이터!$B$8 -> 0.84004413 | G24: =표1_논문데이터!$C$9/표1_논문데이터!$B$9 -> 0.86530843 | H24: =표1_논문데이터!$C$10/표1_논문데이터!$B$10 -> 0.85949506 | I24: =표1_논문데이터!$C$11/표1_논문데이터!$B$11 -> 0.94924242 | J24: =표1_논문데이터!$C$12/표1_논문데이터!$B$12 -> 0.85317252 | K24: =표1_논문데이터!$C$13/표1_논문데이터!$B$13 -> 0.94178628 | L24: =표1_논문데이터!$C$14/표1_논문데이터!$B$14 -> 0.91040289 | M24: =표1_논문데이터!$C$15/표1_논문데이터!$B$15 -> 0.88867562 | N24: =표1_논문데이터!$C$16/표1_논문데이터!$B$16 -> 0.91983122 | O24: VS_m / TS_m (표1)
A25: S_ac 원물 (=FFS_m/M_Sac) | B25: kg COD/m³ | C25: =표1_논문데이터!$D$5/가정!$C$10 -> 6.5173333 | D25: =표1_논문데이터!$D$6/가정!$C$10 -> 3.6053333 | E25: =표1_논문데이터!$D$7/가정!$C$10 -> 3.6053333 | F25: =표1_논문데이터!$D$8/가정!$C$10 -> 1.984 | G25: =표1_논문데이터!$D$9/가정!$C$10 -> 2.4426667 | H25: =표1_논문데이터!$D$10/가정!$C$10 -> 3.52 | I25: =표1_논문데이터!$D$11/가정!$C$10 -> 2.4853333 | J25: =표1_논문데이터!$D$12/가정!$C$10 -> 5.2373333 | K25: =표1_논문데이터!$D$13/가정!$C$10 -> 2.0053333 | L25: =표1_논문데이터!$D$14/가정!$C$10 -> 3.52 | M25: =표1_논문데이터!$D$15/가정!$C$10 -> 4.128 | N25: =표1_논문데이터!$D$16/가정!$C$10 -> 6.2933333 | O25: FFS_m / M_Sac
A26: q (TS 1 kg당 분해성 COD) | B26: kg COD/kg TS | C26: =((1-C14-C15-C16-C17)+C14*C10)/가정!$C$7+C15/가정!$C$8+C16/가정!$C$9 -> 1.2013221 | D26: =((1-D14-D15-D16-D17)+D14*D10)/가정!$C$7+D15/가정!$C$8+D16/가정!$C$9 -> 1.3364139 | E26: =((1-E14-E15-E16-E17)+E14*E10)/가정!$C$7+E15/가정!$C$8+E16/가정!$C$9 -> 1.2722374 | F26: =((1-F14-F15-F16-F17)+F14*F10)/가정!$C$7+F15/가정!$C$8+F16/가정!$C$9 -> 1.205508 | G26: =((1-G14-G15-G16-G17)+G14*G10)/가정!$C$7+G15/가정!$C$8+G16/가정!$C$9 -> 1.3125482 | H26: =((1-H14-H15-H16-H17)+H14*H10)/가정!$C$7+H15/가정!$C$8+H16/가정!$C$9 -> 1.1483281 | I26: =((1-I14-I15-I16-I17)+I14*I10)/가정!$C$7+I15/가정!$C$8+I16/가정!$C$9 -> 1.4167611 | J26: =((1-J14-J15-J16-J17)+J14*J10)/가정!$C$7+J15/가정!$C$8+J16/가정!$C$9 -> 1.1573439 | ... N26: =((1-N14-N15-N16-N17)+N14*N10)/가정!$C$7+N15/가정!$C$8+N16/가정!$C$9 -> 1.2900324 | O26: {[(1−fRF−fRP−fRFe−fRA)+fRF·fOTSrf]/M_Xch + fRP/M_Xpr + fRFe/M_Xli}
A27: X_org 원물 목표 (=COD_m−S_ac 원물) | B27: kg COD/m³ | C27: =표1_논문데이터!$J$5-C25 -> 307.98267 | D27: =표1_논문데이터!$J$6-D25 -> 376.79467 | E27: =표1_논문데이터!$J$7-E25 -> 261.49467 | F27: =표1_논문데이터!$J$8-F25 -> 316.216 | G27: =표1_논문데이터!$J$9-G25 -> 312.95733 | H27: =표1_논문데이터!$J$10-H25 -> 238.68 | I27: =표1_논문데이터!$J$11-I25 -> 314.71467 | J27: =표1_논문데이터!$J$12-J25 -> 213.16267 | K27: =표1_논문데이터!$J$13-K25 -> 143.99467 | L27: =표1_논문데이터!$J$14-L25 -> 212.98 | M27: =표1_논문데이터!$J$15-M25 -> 307.672 | N27: =표1_논문데이터!$J$16-N25 -> 300.90667 | O27: COD_m − S_ac 원물
A28: A (비체적 계수) | B28: m³/kg | C28: =(1-C15-C16-C17)/가정!$C$11+C15/가정!$C$12+C16/가정!$C$13+C17/가정!$C$14-1/가정!$C$16 -> -0.00030772066 | D28: =(1-D15-D16-D17)/가정!$C$11+D15/가정!$C$12+D16/가정!$C$13+D17/가정!$C$14-1/가정!$C$16 -> -0.00027312497 | E28: =(1-E15-E16-E17)/가정!$C$11+E15/가정!$C$12+E16/가정!$C$13+E17/가정!$C$14-1/가정!$C$16 -> -0.00029275654 | F28: =(1-F15-F16-F17)/가정!$C$11+F15/가정!$C$12+F16/가정!$C$13+F17/가정!$C$14-1/가정!$C$16 -> -0.00029918813 | G28: =(1-G15-G16-G17)/가정!$C$11+G15/가정!$C$12+G16/가정!$C$13+G17/가정!$C$14-1/가정!$C$16 -> -0.00027579144 | H28: =(1-H15-H16-H17)/가정!$C$11+H15/가정!$C$12+H16/가정!$C$13+H17/가정!$C$14-1/가정!$C$16 -> -0.00032327371 | I28: =(1-I15-I16-I17)/가정!$C$11+I15/가정!$C$12+I16/가정!$C$13+I17/가정!$C$14-1/가정!$C$16 -> -0.0002605605 | J28: =(1-J15-J16-J17)/가정!$C$11+J15/가정!$C$12+J16/가정!$C$13+J17/가정!$C$14-1/가정!$C$16 -> -0.00031740102 | ... N28: =(1-N15-N16-N17)/가정!$C$11+N15/가정!$C$12+N16/가정!$C$13+N17/가정!$C$14-1/가정!$C$16 -> -0.00028608811 | O28: (1−fRP−fRFe−fRA)/ρ_CH + fRP/ρ_PR + fRFe/ρ_LI + fRA/ρ_MI − 1/ρ_H2O (feedstock._calc_density 분해)
A29: B (비체적 상수) | B29: m³/kg | C29: =(1-(C21/1000))/가정!$C$16+(C21/1000)/가정!$C$15 -> 0.0009999709 | D29: =(1-(D21/1000))/가정!$C$16+(D21/1000)/가정!$C$15 -> 0.0009999839 | E29: =(1-(E21/1000))/가정!$C$16+(E21/1000)/가정!$C$15 -> 0.0009999839 | F29: =(1-(F21/1000))/가정!$C$16+(F21/1000)/가정!$C$15 -> 0.00099999114 | G29: =(1-(G21/1000))/가정!$C$16+(G21/1000)/가정!$C$15 -> 0.0009999891 | H29: =(1-(H21/1000))/가정!$C$16+(H21/1000)/가정!$C$15 -> 0.00099998429 | I29: =(1-(I21/1000))/가정!$C$16+(I21/1000)/가정!$C$15 -> 0.0009999889 | J29: =(1-(J21/1000))/가정!$C$16+(J21/1000)/가정!$C$15 -> 0.00099997662 | ... N29: =(1-(N21/1000))/가정!$C$16+(N21/1000)/가정!$C$15 -> 0.0009999719 | O29: (1−f_AC)/ρ_H2O + f_AC/ρ_AC , f_AC=FFS/1000
A30: TS₀ 원물 (ρ=1000 해, 참고) | B30: kg/t FM | C30: =C27/C26 -> 256.36977 | D30: =D27/D26 -> 281.94458 | E30: =E27/E26 -> 205.53921 | F30: =F27/F26 -> 262.30934 | G30: =G27/G26 -> 238.43492 | H30: =H27/H26 -> 207.85 | I30: =I27/I26 -> 222.13672 | J30: =J27/J26 -> 184.18265 | ... N30: =N27/N26 -> 233.25513 | O30: X_org 원물 / q — 물 타기 전 모델 TS(ρ=1000 기준)
A31: 희석비 R = 1/(1+w_water) | B31: - | C31: =1/(1+가정!$C$28) -> 0.1 | D31: =1/(1+가정!$C$28) -> 0.1 | E31: =1/(1+가정!$C$28) -> 0.1 | F31: =1/(1+가정!$C$28) -> 0.1 | G31: =1/(1+가정!$C$28) -> 0.1 | H31: =1/(1+가정!$C$28) -> 0.1 | I31: =1/(1+가정!$C$28) -> 0.1 | J31: =1/(1+가정!$C$28) -> 0.1 | ... N31: =1/(1+가정!$C$28) -> 0.1 | O31: 1/(1+w_water) [가정 시트]
A32: 소화조 1기 유입량 Q | B32: m³/d | C32: =가정!$C$26 -> 200 | D32: =가정!$C$26 -> 200 | E32: =가정!$C$26 -> 200 | F32: =가정!$C$26 -> 200 | G32: =가정!$C$26 -> 200 | H32: =가정!$C$26 -> 200 | I32: =가정!$C$26 -> 200 | J32: =가정!$C$26 -> 200 | ... N32: =가정!$C$26 -> 200 | O32: Q_feed [가정 시트] — 희석 슬러리 유량 (ρ≈1000)
A33: 원물 투입량 (전체) | B33: t/d | C33: =C32*가정!$C$29/(1+가정!$C$28) -> 20 | D33: =D32*가정!$C$29/(1+가정!$C$28) -> 20 | E33: =E32*가정!$C$29/(1+가정!$C$28) -> 20 | F33: =F32*가정!$C$29/(1+가정!$C$28) -> 20 | G33: =G32*가정!$C$29/(1+가정!$C$28) -> 20 | H33: =H32*가정!$C$29/(1+가정!$C$28) -> 20 | I33: =I32*가정!$C$29/(1+가정!$C$28) -> 20 | J33: =J32*가정!$C$29/(1+가정!$C$28) -> 20 | ... N33: =N32*가정!$C$29/(1+가정!$C$28) -> 20 | O33: Q·N_dig/(1+w_water) — 이 유량에 담긴 원물량
A34: HRT = V/Q | B34: d | C34: =가정!$C$30/C32 -> 30 | D34: =가정!$C$30/D32 -> 30 | E34: =가정!$C$30/E32 -> 30 | F34: =가정!$C$30/F32 -> 30 | G34: =가정!$C$30/G32 -> 30 | H34: =가정!$C$30/H32 -> 30 | I34: =가정!$C$30/I32 -> 30 | J34: =가정!$C$30/J32 -> 30 | ... N34: =가정!$C$30/N32 -> 30 | O34: V_liq / Q
A35: k_1st ≈ Rm/BMP_COD (논문 BMP 1차 분해속도) | B35: d⁻¹ | C35: =표1_논문데이터!$N$5/표1_논문데이터!$L$5 -> 0.2187066 | D35: =표1_논문데이터!$N$6/표1_논문데이터!$L$6 -> 0.33689974 | E35: =표1_논문데이터!$N$7/표1_논문데이터!$L$7 -> 0.35767669 | F35: =표1_논문데이터!$N$8/표1_논문데이터!$L$8 -> 0.32891711 | G35: =표1_논문데이터!$N$9/표1_논문데이터!$L$9 -> 0.3904193 | H35: =표1_논문데이터!$N$10/표1_논문데이터!$L$10 -> 0.30714348 | I35: =표1_논문데이터!$N$11/표1_논문데이터!$L$11 -> 0.28415868 | J35: =표1_논문데이터!$N$12/표1_논문데이터!$L$12 -> 0.23870919 | K35: =표1_논문데이터!$N$13/표1_논문데이터!$L$13 -> 0.2516469 | L35: =표1_논문데이터!$N$14/표1_논문데이터!$L$14 -> 0.34940702 | M35: =표1_논문데이터!$N$15/표1_논문데이터!$L$15 -> 0.44440261 | N35: =표1_논문데이터!$N$16/표1_논문데이터!$L$16 -> 0.20375746 | O35: Rm_m / BMP_COD,m (표1) — modified Gompertz 최대속도를 1차 속도상수로 환산. 0.20~0.44 → 음식물은 빠른 풀
A36: S_ac 희석 후 (=R·S_ac 원물) | B36: kg COD/m³ | C36: =C25*C31 -> 0.65173333 | D36: =D25*D31 -> 0.36053333 | E36: =E25*E31 -> 0.36053333 | F36: =F25*F31 -> 0.1984 | G36: =G25*G31 -> 0.24426667 | H36: =H25*H31 -> 0.352 | I36: =I25*I31 -> 0.24853333 | J36: =J25*J31 -> 0.52373333 | ... N36: =N25*N31 -> 0.62933333 | O36: R·S_ac 원물
A37: X_org 목표 희석 후 (=R·X_org 원물) | B37: kg COD/m³ | C37: =C27*C31 -> 30.798267 | D37: =D27*D31 -> 37.679467 | E37: =E27*E31 -> 26.149467 | F37: =F27*F31 -> 31.6216 | G37: =G27*G31 -> 31.295733 | H37: =H27*H31 -> 23.868 | I37: =I27*I31 -> 31.471467 | J37: =J27*J31 -> 21.316267 | ... N37: =N27*N31 -> 30.090667 | O37: R·X_org 원물
A38: TS₀ (ρ=1000 해) | B38: kg/t FM | C38: =C37/C26 -> 25.636977 | D38: =D37/D26 -> 28.194458 | E38: =E37/E26 -> 20.553921 | F38: =F37/F26 -> 26.230934 | G38: =G37/G26 -> 23.843492 | H38: =H37/H26 -> 20.785 | I38: =I37/I26 -> 22.213672 | J38: =J37/J26 -> 18.418265 | ... N38: =N37/N26 -> 23.325513 | O38: X_org / q (TS<200이면 ρ=1000 이므로 이 값이 해)
A39: TS_c (밀도식 폐형해) | B39: kg/t FM | C39: =1000*C37*C29/(C26-C37*C28) -> 25.435569 | D39: =1000*D37*D29/(D26-D37*D28) -> 27.978553 | E39: =1000*E37*E29/(E26-E37*E28) -> 20.430653 | F39: =1000*F37*F29/(F26-F37*F28) -> 26.026446 | G39: =1000*G37*G29/(G26-G37*G28) -> 23.687468 | H39: =1000*H37*H29/(H26-H37*H28) -> 20.645948 | I39: =1000*I37*I29/(I26-I37*I28) -> 22.085594 | J39: =1000*J37*J29/(J26-J37*J28) -> 18.31079 | ... N39: =1000*N37*N29/(N26-N37*N28) -> 23.170239 | O39: 1000·X·B/(q−X·A) (TS≥200: X = fTS·ρ·q, ρ=1/(A·fTS+B) 를 fTS에 대해 정리)
A40: ρ_FM (라이브러리 밀도) | B40: kg/m³ | C40: =IF(C5<200,1000,1/(C28*C5/1000+C29)) -> 1000 | D40: =IF(D5<200,1000,1/(D28*D5/1000+D29)) -> 1000 | E40: =IF(E5<200,1000,1/(E28*E5/1000+E29)) -> 1000 | F40: =IF(F5<200,1000,1/(F28*F5/1000+F29)) -> 1000 | G40: =IF(G5<200,1000,1/(G28*G5/1000+G29)) -> 1000 | H40: =IF(H5<200,1000,1/(H28*H5/1000+H29)) -> 1000 | I40: =IF(I5<200,1000,1/(I28*I5/1000+I29)) -> 1000 | J40: =IF(J5<200,1000,1/(J28*J5/1000+J29)) -> 1000 | ... N40: =IF(N5<200,1000,1/(N28*N5/1000+N29)) -> 1000 | O40: TS<200 → 1000 , TS≥200 → 1/(A·TS/1000+B)
A41: VS 희석 후 | B41: kg/m³ | C41: =C5*C40/1000*(1-C17) -> 23.1009 | D41: =D5*D40/1000*(1-D17) -> 25.171738 | E41: =E5*E40/1000*(1-E17) -> 18.90551 | F41: =F5*F40/1000*(1-F17) -> 22.035142 | G41: =G5*G40/1000*(1-G17) -> 20.631975 | H41: =H5*H40/1000*(1-H17) -> 17.864605 | I41: =I5*I40/1000*(1-I17) -> 21.08616 | J41: =J5*J40/1000*(1-J17) -> 15.713957 | ... N41: =N5*N40/1000*(1-N17) -> 21.455535 | O41: TS·ρ/1000·(1−fRA)
A42: OLR = Q·VS/V | B42: kg VS/m³/d | C42: =C32*C41/가정!$C$30 -> 0.77003 | D42: =D32*D41/가정!$C$30 -> 0.83905793 | E42: =E32*E41/가정!$C$30 -> 0.63018365 | F42: =F32*F41/가정!$C$30 -> 0.73450473 | G42: =G32*G41/가정!$C$30 -> 0.6877325 | H42: =H32*H41/가정!$C$30 -> 0.59548683 | I42: =I32*I41/가정!$C$30 -> 0.70287201 | J42: =J32*J41/가정!$C$30 -> 0.52379858 | ... N42: =N32*N41/가정!$C$30 -> 0.7151845 | O42: Q·VS/V_liq — 물을 타도 VS 질량 부하는 변하지 않음
...

Sheet 가정
A1: 가정·상수 (파란 글씨 = 수정 가능한 입력)
A2: 기호 | B2: 설명 | C2: 값 | D2: 근거/비고
A3: Y_loss | B3: 미생물 합성 손실 비율(BMP→분해가능 COD 환산) | C3: 0.06 | D3: 가정 — 실제 ADM1 모사에서 CH4 수율 보정 필요
A4: CH4th | B4: COD당 이론 CH4 [Nm³/kg COD] | C4: 0.3502 | D4: PyADM1ODE: V_m/(CH4_cod_2_mol/1000)=0.022413/0.064
A5: fRF | B5: 조섬유 분율 [-TS] | C5: 0.04 | D5: 가정 — 논문에 없음, 민감도 낮음(±1% COD)
A6: fOTSrf | B6: 조섬유 중 분해가능 비율 [-] | C6: 0.8 | D6: 가정 — 논문에 없음
A7: M_Xch | B7: 탄수화물 질량/COD [kg/kg] | C7: 0.9375 | D7: PyADM1ODE SubstrateParams 기본값
A8: M_Xpr | B8: 단백질 질량/COD [kg/kg] | C8: 0.7736 | D8: PyADM1ODE 기본값
A9: M_Xli | B9: 지방 질량/COD [kg/kg] | C9: 0.34741379 | D9: PyADM1ODE 기본값
A10: M_Sac | B10: 아세트산 질량/COD [kg/kg] | C10: 0.9375 | D10: PyADM1ODE 기본값
A11: roh_CH | B11: 탄수화물 밀도 [kg/m³] | C11: 1550 | D11: PyADM1ODE 기본값
A12: roh_PR | B12: 단백질 밀도 [kg/m³] | C12: 1370 | D12: PyADM1ODE 기본값
A13: roh_LI | B13: 지방 밀도 [kg/m³] | C13: 920 | D13: PyADM1ODE 기본값
A14: roh_MI | B14: 회분 밀도 [kg/m³] | C14: 2420 | D14: PyADM1ODE 기본값
... A38: H_H2S_298 | B38: H₂S Henry 상수 H_cp(298 K) [mol/(m³·Pa)] | C38: 0.001 | D38: Sander 2015, −dlnH/d(1/T)=2100 K → 35 ℃ 7.96e-4; pKa1 7.05(25 ℃)→6.92(35 ℃)
